test_0 (__main__.lab2a)
[Lab 2] - [Investigation 1] - [Part 1] - variables & printing - Test for file creation: ./lab2a.py ... ok
test_1 (__main__.lab2a)
[Lab 2] - [Investigation 1] - [Part 1] - variables & printing - Test for errors running: ./lab2a.py ... /usr/lib/python3.10/subprocess.py:767: ResourceWarning: unclosed file <_io.TextIOWrapper name=3 encoding='UTF-8'>
  _cleanup()
ResourceWarning: Enable tracemalloc to get the object allocation traceback
ok
test_2 (__main__.lab2a)
[Lab 2] - [Investigation 1] - [Part 1] - variables & printing - Test for correct shebang line: ./lab2a.py ... FAIL

======================================================================
FAIL: test_2 (__main__.lab2a)
[Lab 2] - [Investigation 1] - [Part 1] - variables & printing - Test for correct shebang line: ./lab2a.py
----------------------------------------------------------------------
Traceback (most recent call last):
  File "/home/twangmo12/OPS445-ZAA/lab2/./CheckLab2.py", line 63, in test_2
    self.assertEqual(first_line.strip(), '#!/usr/bin/env python3', msg=error_output)
AssertionError: '' != '#!/usr/bin/env python3'
+ #!/usr/bin/env python3 : lab2a.py does not have the correct shebang line (HINT: what should the first line contain)

----------------------------------------------------------------------
Ran 3 tests in 0.011s

FAILED (failures=1)
OPS445 Lab Report - System Information for running ./CheckLab2.py
=================================================================
    User login name: twangmo12
    Git Email: twangmo12@myseneca.ca
    Linux system name: Tandin-Wangmo
    Python executable: /usr/bin/python3
    Python version:  3.10.12 (main, Jun 11 2023, 05:26:28) [GCC 11.4.0]
    OS Platform: linux
    Working Directory: /home/twangmo12/OPS445-ZAA/lab2
    Start at: Wed Sep 25 09:53:33 2024
=================================================================
